<?xml version="1.0" ?>
<!-- =================================================================================== -->
<!-- |    This document was autogenerated by xacro from ../../../trunk/pr2_common/pr2_description/robots/pr2.urdf.xacro | -->
<!-- |    EDITING THIS FILE BY HAND IS NOT RECOMMENDED                                 | -->
<!-- =================================================================================== -->
<robot name="pr2" xmlns:body="http://playerstage.sourceforge.net/gazebo/xmlschema/#body" xmlns:controller="http://playerstage.sourceforge.net/gazebo/xmlschema/#controller" xmlns:geom="http://playerstage.sourceforge.net/gazebo/xmlschema/#geom" xmlns:interface="http://playerstage.sourceforge.net/gazebo/xmlschema/#interface" xmlns:joint="http://playerstage.sourceforge.net/gazebo/xmlschema/#slider" xmlns:sensor="http://playerstage.sourceforge.net/gazebo/xmlschema/#sensor" xmlns:xacro="http://ros.org/wiki/xacro">
  <!-- The following included files set up definitions of parts of the robot body -->
  <!-- misc common stuff? -->
  <!-- PR2 Arm -->
  <!-- PR2 gripper -->
  <!-- PR2 head -->
  <!-- PR2 tilting laser mount -->
  <!-- PR2 torso -->
  <!-- PR2 base -->
  <!-- Head sensors -->
  <!-- Camera sensors -->
  <!-- Texture projector -->
  <!-- generic simulator_gazebo plugins for starting mechanism control, ros time, ros battery -->
  <gazebo>
    <controller:gazebo_ros_controller_manager name="gazebo_ros_controller_manager" plugin="libgazebo_ros_controller_manager.so">
      <alwaysOn>true</alwaysOn>
      <updateRate>1000.0</updateRate>
      <interface:audio name="gazebo_ros_controller_manager_dummy_iface"/>
    </controller:gazebo_ros_controller_manager>
    <controller:gazebo_ros_power_monitor name="gazebo_ros_power_monitor_controller" plugin="libgazebo_ros_power_monitor.so">
      <alwaysOn>true</alwaysOn>
      <updateRate>1.0</updateRate>
      <timeout>5</timeout>
      <interface:audio name="power_monitor_dummy_interface"/>
      <powerStateTopic>power_state</powerStateTopic>
      <powerStateRate>10.0</powerStateRate>
      <fullChargeCapacity>87.78</fullChargeCapacity>
      <dischargeRate>-474</dischargeRate>
      <chargeRate>525</chargeRate>
      <dischargeVoltage>15.52</dischargeVoltage>
      <chargeVoltage>16.41</chargeVoltage>
    </controller:gazebo_ros_power_monitor>
  </gazebo>
  <!-- materials for visualization -->
  <material name="Blue">
    <color rgba="0.0 0.0 0.8 1.0"/>
  </material>
  <material name="Green">
    <color rgba="0.0 0.8 0.0 1.0"/>
  </material>
  <material name="Grey">
    <color rgba="0.7 0.7 0.7 1.0"/>
  </material>
  <material name="Grey2">
    <color rgba="0.9 0.9 0.9 1.0"/>
  </material>
  <material name="Red">
    <color rgba="0.8 0.0 0.0 1.0"/>
  </material>
  <material name="White">
    <color rgba="1.0 1.0 1.0 1.0"/>
  </material>
  <material name="Caster">
    <texture filename="package://pr2_ogre/Media/materials/textures/pr2_caster_texture.png"/>
  </material>
  <material name="Wheel_l">
    <texture filename="package://pr2_ogre/Media/materials/textures/pr2_wheel_left.png"/>
  </material>
  <material name="Wheel_r">
    <texture filename="package://pr2_ogre/Media/materials/textures/pr2_wheel_right.png"/>
  </material>
  <material name="RollLinks">
    <texture filename="package://pr2_ogre/Media/materials/textures/pr2_wheel_left.png"/>
  </material>
  <!-- Now we can start using the macros included above to define the actual PR2 -->
  <!-- The first use of a macro.  This one was defined in base.urdf.xacro above.
       A macro like this will expand to a set of link and joint definitions, and to additional
       Gazebo-related extensions (sensor plugins, etc).  The macro takes an argument, name, 
       that equals "base", and uses it to generate names for its component links and joints 
       (e.g., base_link).  The included origin block is also an argument to the macro.  By convention, 
       the origin block defines where the component is w.r.t its parent (in this case the parent 
       is the world frame). For more, see http://www.ros.org/wiki/xacro -->
  
 
  <joint name="r_gripper_palm_joint" type="fixed">
    <origin rpy="0 0 0" xyz="0 0 0"/>
    <parent link="r_wrist_roll_link"/>
    <child link="r_gripper_palm_link"/>
  </joint>
  <link name="r_gripper_palm_link">
    <inertial>
      <mass value="0.58007"/>
      <origin rpy="0 0 0" xyz="0.06623 0.00053 -0.00119"/>
      <inertia ixx="0.00035223921" ixy="-0.00001580476" ixz="-0.00000091750" iyy="0.00067741312" iyz="-0.00000059554" izz="0.00086563316"/>
    </inertial>
    <visual>
      <origin rpy="0 0 0" xyz="0 0 0"/>
      <geometry>
        <mesh filename="package://pr2_description/meshes/gripper_v0/gripper_palm.dae"/>
      </geometry>
      <material name="Red"/>
    </visual>
    <collision>
      <origin rpy="0 0 0" xyz="0 0 0"/>
      <geometry>
        <mesh filename="package://pr2_description/meshes/gripper_v0/gripper_palm.stl"/>
      </geometry>
      <verbose value="Yes"/>
    </collision>
  </link>
  <joint name="r_gripper_led_joint" type="fixed">
    <!--  Need to check if we need a positive or negative Z term -->
    <origin xyz="0.0513 0.0 .0244"/>
    <parent link="r_gripper_palm_link"/>
    <child link="r_gripper_led_frame"/>
  </joint>
  <link name="r_gripper_led_frame"/>
  <joint name="r_gripper_motor_accelerometer_joint" type="fixed">
    <origin rpy="0 0 0" xyz="0 0 0"/>
    <parent link="r_gripper_palm_link"/>
    <child link="r_gripper_motor_accelerometer_link"/>
  </joint>
  <link name="r_gripper_motor_accelerometer_link">
    <inertial>
      <mass value="0.001"/>
      <origin rpy="0 0 0" xyz="0 0 0"/>
      <inertia ixx="0.001" ixy="0.0" ixz="0.0" iyy="0.001" iyz="0.0" izz="0.001"/>
    </inertial>
    <visual>
      <origin rpy="0 0 0" xyz="0 0 0"/>
      <geometry>
        <box size="0.001 0.001 0.001"/>
      </geometry>
    </visual>
    <collision>
      <origin rpy="0 0 0" xyz="0 0 0"/>
      <geometry>
        <box size="0.001 0.001 0.001"/>
      </geometry>
    </collision>
  </link>
  <joint name="r_gripper_tool_joint" type="fixed">
    <origin rpy="0 0 0" xyz="0.18 0 0"/>
    <parent link="r_gripper_palm_link"/>
    <child link="r_gripper_tool_frame"/>
  </joint>
  <link name="r_gripper_tool_frame"/>
  <joint name="r_gripper_l_finger_joint" type="revolute">
    <axis xyz="0 0 1"/>
    <limit effort="1000.0" lower="0.0" upper="0.548" velocity="0.5"/>
    <dynamics damping="0.2"/>
    <origin rpy="0 0 0" xyz="0.07691 0.01 0"/>
    <parent link="r_gripper_palm_link"/>
    <child link="r_gripper_l_finger_link"/>
  </joint>
  <link name="r_gripper_l_finger_link">
    <inertial>
      <mass value="0.17126"/>
      <origin rpy="0 0 0" xyz="0.03598 0.01730 -0.00164"/>
      <inertia ixx="0.00007756198" ixy="0.00000149095" ixz="-0.00000983385" iyy="0.00019708305" iyz="-0.00000306125" izz="0.00018105446"/>
    </inertial>
    <visual>
      <origin rpy="0 0 0" xyz="0 0 0"/>
      <geometry>
        <mesh filename="package://pr2_description/meshes/gripper_v0/l_finger.dae"/>
      </geometry>
      <material name="Grey"/>
    </visual>
    <collision>
      <origin rpy="0 0 0" xyz="0 0 0"/>
      <geometry>
        <mesh filename="package://pr2_description/meshes/gripper_v0/l_finger.stl"/>
      </geometry>
      <verbose value="Yes"/>
    </collision>
  </link>
  <joint name="r_gripper_r_finger_joint" type="revolute">
    <axis xyz="0 0 -1"/>
    <origin rpy="0 0 0" xyz="0.07691 -0.01 0"/>
    <limit effort="1000.0" lower="0.0" upper="0.548" velocity="0.5"/>
    <dynamics damping="0.2"/>
    <mimic joint="r_gripper_l_finger_joint" multiplier="1" offset="0"/>
    <parent link="r_gripper_palm_link"/>
    <child link="r_gripper_r_finger_link"/>
  </joint>
  <link name="r_gripper_r_finger_link">
    <inertial>
      <mass value="0.17389"/>
      <origin rpy="0 0 0" xyz="0.03576 -0.01736 -0.00095"/>
      <inertia ixx="0.00007738410" ixy="-0.00000209309" ixz="-0.00000836228" iyy="0.00019847383" iyz="0.00000246110" izz="0.00018106988"/>
    </inertial>
    <visual>
      <origin rpy="3.14159265359 0 0" xyz="0 0 0"/>
      <geometry>
        <mesh filename="package://pr2_description/meshes/gripper_v0/l_finger.dae"/>
      </geometry>
      <material name="Grey"/>
    </visual>
    <collision>
      <origin rpy="3.14159265359 0 0" xyz="0 0 0"/>
      <geometry>
        <mesh filename="package://pr2_description/meshes/gripper_v0/l_finger.stl"/>
      </geometry>
      <verbose value="Yes"/>
    </collision>
  </link>
  <joint name="r_gripper_l_finger_tip_joint" type="revolute">
    <axis xyz="0 0 -1"/>
    <origin rpy="0 0 0" xyz="0.09137 0.00495 0"/>
    <limit effort="1000.0" lower="0.0" upper="0.548" velocity="0.5"/>
    <dynamics damping="0.01"/>
    <mimic joint="r_gripper_l_finger_joint" multiplier="1" offset="0"/>
    <parent link="r_gripper_l_finger_link"/>
    <child link="r_gripper_l_finger_tip_link"/>
  </joint>
  <link name="r_gripper_l_finger_tip_link">
    <inertial>
      <mass value="0.04419"/>
      <origin rpy="0 0 0" xyz="0.00423 0.00284 0.0"/>
      <inertia ixx="0.00000837047" ixy="0.00000583632" ixz="0.0" iyy="0.00000987067" iyz="0.0" izz="0.00001541768"/>
    </inertial>
    <visual>
      <origin rpy="0 0 0" xyz="0 0 0"/>
      <geometry>
        <mesh filename="package://pr2_description/meshes/gripper_v0/l_finger_tip.dae"/>
      </geometry>
      <material name="Green"/>
    </visual>
    <collision>
      <origin rpy="0 0 0" xyz="0 0 0"/>
      <geometry>
        <mesh filename="package://pr2_description/meshes/gripper_v0/l_finger_tip.stl"/>
      </geometry>
      <verbose value="Yes"/>
    </collision>
  </link>
  <joint name="r_gripper_r_finger_tip_joint" type="revolute">
    <axis xyz="0 0 1"/>
    <origin rpy="0 0 0" xyz="0.09137 -0.00495 0"/>
    <limit effort="1000.0" lower="0.0" upper="0.548" velocity="0.5"/>
    <dynamics damping="0.01"/>
    <mimic joint="r_gripper_l_finger_joint" multiplier="1" offset="0"/>
    <parent link="r_gripper_r_finger_link"/>
    <child link="r_gripper_r_finger_tip_link"/>
  </joint>
  <link name="r_gripper_r_finger_tip_link">
    <inertial>
      <mass value="0.04419"/>
      <origin rpy="0 0 0" xyz="0.00423 -0.00284 0.0"/>
      <inertia ixx="0.00000837047" ixy="-0.00000583632" ixz="0.0" iyy="0.00000987067" iyz="0.0" izz="0.00001541768"/>
    </inertial>
    <visual>
      <origin rpy="3.14159265359 0 0" xyz="0 0 0"/>
      <geometry>
        <mesh filename="package://pr2_description/meshes/gripper_v0/l_finger_tip.dae"/>
      </geometry>
      <material name="Green"/>
    </visual>
    <collision>
      <origin rpy="3.14159265359 0 0" xyz="0 0 0"/>
      <geometry>
        <mesh filename="package://pr2_description/meshes/gripper_v0/l_finger_tip.stl"/>
      </geometry>
      <verbose value="Yes"/>
    </collision>
  </link>
  <gazebo reference="r_gripper_l_finger_link">
    <turnGravityOff>true</turnGravityOff>
    <sensor:contact name="r_gripper_l_finger_contact_sensor">
      <geom>r_gripper_l_finger_link_geom</geom>
      <updateRate>100.0</updateRate>
      <controller:gazebo_ros_bumper name="r_gripper_l_finger_gazebo_ros_bumper_controller" plugin="libgazebo_ros_bumper.so">
        <alwaysOn>true</alwaysOn>
        <updateRate>100.0</updateRate>
        <bumperTopicName>r_gripper_l_finger_bumper</bumperTopicName>
        <interface:bumper name="r_gripper_l_finger_gazebo_ros_bumper_iface"/>
      </controller:gazebo_ros_bumper>
    </sensor:contact>
    <mu1 value="500.0"/>
    <mu2 value="500.0"/>
    <kp value="1000000.0"/>
    <kd value="1.0"/>
    <!-- for "${prefix}_l_finger_joint"-->
  </gazebo>
  <gazebo reference="r_gripper_l_finger_joint">
    <stopKd value="1.0"/>
    <stopKp value="10000000.0"/>
    <fudgeFactor value="1.0"/>
    <provideFeedback value="true"/>
  </gazebo>
  <gazebo reference="r_gripper_r_finger_link">
    <turnGravityOff>true</turnGravityOff>
    <sensor:contact name="r_gripper_r_finger_contact_sensor">
      <geom>r_gripper_r_finger_link_geom</geom>
      <updateRate>100.0</updateRate>
      <controller:gazebo_ros_bumper name="r_gripper_r_finger_gazebo_ros_bumper_controller" plugin="libgazebo_ros_bumper.so">
        <alwaysOn>true</alwaysOn>
        <updateRate>100.0</updateRate>
        <bumperTopicName>r_gripper_r_finger_bumper</bumperTopicName>
        <interface:bumper name="r_gripper_r_finger_gazebo_ros_bumper_iface"/>
      </controller:gazebo_ros_bumper>
    </sensor:contact>
    <mu1 value="500.0"/>
    <mu2 value="500.0"/>
    <kp value="1000000.0"/>
    <kd value="1.0"/>
  </gazebo>
  <gazebo reference="r_gripper_r_finger_joint">
    <stopKd value="1.0"/>
    <stopKp value="10000000.0"/>
    <fudgeFactor value="1.0"/>
    <provideFeedback value="true"/>
  </gazebo>
  <gazebo reference="r_gripper_l_finger_tip_link">
    <turnGravityOff>true</turnGravityOff>
    <selfCollide>false</selfCollide>
    <sensor:contact name="r_gripper_l_finger_tip_contact_sensor">
      <geom>r_gripper_l_finger_tip_link_geom</geom>
      <updateRate>100.0</updateRate>
      <controller:gazebo_ros_bumper name="r_gripper_l_finger_tip_gazebo_ros_bumper_controller" plugin="libgazebo_ros_bumper.so">
        <alwaysOn>true</alwaysOn>
        <updateRate>100.0</updateRate>
        <bumperTopicName>r_gripper_l_finger_tip_bumper</bumperTopicName>
        <interface:bumper name="r_gripper_l_finger_tip_gazebo_ros_bumper_iface"/>
      </controller:gazebo_ros_bumper>
    </sensor:contact>
    <mu1 value="500.0"/>
    <mu2 value="500.0"/>
    <kp value="10000000.0"/>
    <kd value="1.0"/>
  </gazebo>
  <gazebo reference="r_gripper_l_finger_tip_joint">
    <stopKd value="1.0"/>
    <stopKp value="10000000.0"/>
    <fudgeFactor value="1.0"/>
    <provideFeedback value="true"/>
  </gazebo>
  <gazebo reference="r_gripper_r_finger_tip_link">
    <turnGravityOff>true</turnGravityOff>
    <selfCollide>false</selfCollide>
    <sensor:contact name="r_gripper_r_finger_tip_contact_sensor">
      <geom>r_gripper_r_finger_tip_link_geom</geom>
      <updateRate>100.0</updateRate>
      <controller:gazebo_ros_bumper name="r_gripper_r_finger_tip_gazebo_ros_bumper_controller" plugin="libgazebo_ros_bumper.so">
        <alwaysOn>true</alwaysOn>
        <updateRate>100.0</updateRate>
        <bumperTopicName>r_gripper_r_finger_tip_bumper</bumperTopicName>
        <interface:bumper name="r_gripper_r_finger_tip_gazebo_ros_bumper_iface"/>
      </controller:gazebo_ros_bumper>
    </sensor:contact>
    <mu1 value="500.0"/>
    <mu2 value="500.0"/>
    <kp value="10000000.0"/>
    <kd value="1.0"/>
  </gazebo>
  <gazebo>
    <controller:gazebo_ros_p3d name="p3d_r_gripper_l_finger_controller" plugin="libgazebo_ros_p3d.so">
      <alwaysOn>true</alwaysOn>
      <updateRate>100.0</updateRate>
      <bodyName>r_gripper_l_finger_link</bodyName>
      <topicName>r_gripper_l_finger_pose_ground_truth</topicName>
      <gaussianNoise>0.0</gaussianNoise>
      <frameName>base_link</frameName>
      <interface:position name="p3d_r_gripper_l_finger_position_iface"/>
    </controller:gazebo_ros_p3d>
    <controller:gazebo_ros_f3d name="f3d_r_gripper_l_finger_controller" plugin="libgazebo_ros_f3d.so">
      <alwaysOn>true</alwaysOn>
      <updateRate>100.0</updateRate>
      <bodyName>r_gripper_l_finger_link</bodyName>
      <topicName>r_gripper_l_finger_force_ground_truth</topicName>
      <frameName>r_gripper_l_finger_link</frameName>
      <interface:position name="f3d_r_gripper_l_finger_force_iface"/>
    </controller:gazebo_ros_f3d>
  </gazebo>
  <gazebo reference="r_gripper_r_finger_tip_joint">
    <stopKd value="1.0"/>
    <stopKp value="10000000.0"/>
    <fudgeFactor value="1.0"/>
    <provideFeedback value="true"/>
  </gazebo>
  <gazebo>
    <body:box name="r_gripper_l_parallel_link">
      <massMatrix>true</massMatrix>
      <mass>0.17126</mass>
      <ixx>7.7562e-05</ixx>
      <ixy>1.49095e-06</ixy>
      <ixz>-9.83385e-06</ixz>
      <iyy>0.000197083</iyy>
      <iyz>-3.06125e-06</iyz>
      <izz>0.000181054</izz>
      <cx>0.03598</cx>
      <cy>0.0173</cy>
      <cz>-0.00164</cz>
      <xyz>0.82991 -0.157 0.790675</xyz>
      <rpy>0 -0 0</rpy>
      <turnGravityOff>true</turnGravityOff>
      <selfCollide>false</selfCollide>
    </body:box>
    <body:box name="r_gripper_r_parallel_link">
      <massMatrix>true</massMatrix>
      <mass>0.17389</mass>
      <ixx>7.73841e-05</ixx>
      <ixy>-2.09309e-06</ixy>
      <ixz>-8.36228e-06</ixz>
      <iyy>0.000198474</iyy>
      <iyz>2.4611e-06</iyz>
      <izz>0.00018107</izz>
      <cx>0.03576</cx>
      <cy>-0.01736</cy>
      <cz>-0.00095</cz>
      <xyz>0.82991 -0.219 0.790675</xyz>
      <rpy>0 -0 0</rpy>
      <turnGravityOff>true</turnGravityOff>
      <selfCollide>false</selfCollide>
    </body:box>
  </gazebo>
  <gazebo>
    <joint:hinge name="r_gripper_r_parallel_root_joint">
      <body1>r_gripper_r_parallel_link</body1>
      <body2>r_gripper_palm_link</body2>
      <anchor>r_gripper_palm_link</anchor>
      <axis>0 0 -1</axis>
      <damping>0.2</damping>
      <anchorOffset>0.05891 -0.031 0</anchorOffset>
    </joint:hinge>
    <joint:hinge name="r_gripper_l_parallel_root_joint">
      <body1>r_gripper_l_parallel_link</body1>
      <body2>r_gripper_palm_link</body2>
      <anchor>r_gripper_palm_link</anchor>
      <axis>0 0 1</axis>
      <damping>0.2</damping>
      <anchorOffset>0.05891 0.031 0</anchorOffset>
    </joint:hinge>
    <joint:hinge name="r_gripper_r_parallel_tip_joint">
      <body1>r_gripper_r_parallel_link</body1>
      <body2>r_gripper_r_finger_tip_link</body2>
      <anchor>r_gripper_r_finger_tip_link</anchor>
      <axis>0 0 1</axis>
      <anchorOffset>-0.018 -0.021 0</anchorOffset>
    </joint:hinge>
    <joint:hinge name="r_gripper_l_parallel_tip_joint">
      <body1>r_gripper_l_parallel_link</body1>
      <body2>r_gripper_l_finger_tip_link</body2>
      <anchor>r_gripper_l_finger_tip_link</anchor>
      <axis>0 0 1</axis>
      <anchorOffset>-0.018 0.021 0</anchorOffset>
    </joint:hinge>
    <joint:slider name="r_gripper_joint">
      <body1>r_gripper_l_finger_tip_link</body1>
      <body2>r_gripper_r_finger_tip_link</body2>
      <anchor>r_gripper_r_finger_tip_link</anchor>
      <axis>0 1 0</axis>
    </joint:slider>
  </gazebo>
  <gazebo reference="r_gripper_l_parallel_link">
    <turnGravityOff>true</turnGravityOff>
    <material value="PR2/Red"/>
  </gazebo>
  <gazebo reference="r_gripper_r_parallel_link">
    <turnGravityOff>true</turnGravityOff>
    <material value="PR2/Red"/>
  </gazebo>
  <joint name="r_gripper_joint" type="prismatic">
    <parent link="r_gripper_r_finger_tip_link"/>
    <child link="r_gripper_l_finger_tip_frame"/>
    <axis xyz="0 1 0"/>
    <dynamics damping="100.0"/>
    <limit effort="1000.0" lower="0.0" upper="0.09" velocity="0.2"/>
    <safety_controller k_position="20.0" k_velocity="5000.0" soft_lower_limit="-0.01" soft_upper_limit="0.088"/>
  </joint>
  <link name="r_gripper_l_finger_tip_frame"/>
  <gazebo reference="r_gripper_palm_link">
    <turnGravityOff>true</turnGravityOff>
    <sensor:contact name="r_gripper_palm_contact_sensor">
      <geom>r_gripper_palm_link_geom</geom>
      <updateRate>100.0</updateRate>
      <controller:gazebo_ros_bumper name="r_gripper_palm_gazebo_ros_bumper_controller" plugin="libgazebo_ros_bumper.so">
        <alwaysOn>true</alwaysOn>
        <updateRate>100.0</updateRate>
        <bumperTopicName>r_gripper_palm_bumper</bumperTopicName>
        <interface:bumper name="r_gripper_palm_gazebo_ros_bumper_iface"/>
      </controller:gazebo_ros_bumper>
    </sensor:contact>
  </gazebo>
  <gazebo>
    <controller:gazebo_ros_p3d name="p3d_r_gripper_palm_controller" plugin="libgazebo_ros_p3d.so">
      <alwaysOn>true</alwaysOn>
      <updateRate>100.0</updateRate>
      <bodyName>r_gripper_palm_link</bodyName>
      <topicName>r_gripper_palm_pose_ground_truth</topicName>
      <xyzOffsets>0 0 0</xyzOffsets>
      <rpyOffsets>0 0 0</rpyOffsets>
      <gaussianNoise>0.0</gaussianNoise>
      <frameName>map</frameName>
      <interface:position name="p3d_r_gripper_palm_position_iface"/>
    </controller:gazebo_ros_p3d>
  </gazebo>
  <transmission name="r_gripper_trans" type="pr2_mechanism_model/PR2GripperTransmission">
    <actuator name="r_gripper_motor"/>
    <gap_joint L0="0.0375528" a="0.0683698" b="0.0433849" gear_ratio="40.095" h="0.0" mechanical_reduction="1.0" name="r_gripper_joint" phi0="0.518518122146" r="0.0915" screw_reduction="0.004" t0="-0.0001914" theta0="0.0628824676201"/>
    <!-- if a gazebo joint exists as [l|r]_gripper_joint, use this tag to have
           gripper transmission apply torque directly to prismatic joint -->
    <use_simulated_gripper_joint/>
    <passive_joint name="r_gripper_l_finger_joint"/>
    <passive_joint name="r_gripper_r_finger_joint"/>
    <passive_joint name="r_gripper_r_finger_tip_joint"/>
    <passive_joint name="r_gripper_l_finger_tip_joint"/>
  </transmission>
</robot>
